Workbook

Sheet 0. Como Alimentar
A1: 0. COMO ALIMENTAR — VERSÃO MULTI-MÊS CONSOLIDADA
A2: Alimente as bases transacionais (1, 2, 3, 10, 12 e 13) e deixe os relatórios recalcularem. Não edite manualmente as abas analíticas.
A4: CONTROLES
A5: Saldo inicial do fluxo de caixa | B5: 0 | C5: Valor usado na aba 4. Fluxo de Caixa.
A6: Ano-base da DRE mensal | B6: 2026 | C6: Muda a aba 7 para o ano desejado.
A7: Mês de análise (1º dia do mês) | B7: 46082 | C7: Muda as abas 8 e 9 para o mês selecionado.
A8: Último mês no CR | B8: =MAX('2. Contas a Receber'!$N$8:$N$1000) | C8: Leitura automática da base de CR.
A9: Último mês no CP | B9: =MAX('3. Contas a Pagar'!$B$6:$B$1000) | C9: Leitura automática da base de CP.
A12: PASSO A PASSO
A13: 1) Lance novos meses em 2. Contas a Receber e 3. Contas a Pagar nas primeiras linhas vazias.
A14: 2) Se surgir cliente novo, cadastre em 10. Cadastro de Clientes.
A15: 3) Se surgir serviço novo, cadastre em 11. Cadastro de Serviços.
A16: 4) Se surgir contrato recorrente ou OS nova, cadastre em 12. Contratos_OS.
A17: 5) Para rastrear ponta a ponta, espelhe cada novo título em 13. Mapa Títulos-Receita.
A18: 6) Revise 14. Consolidado Mensal, 7. DRE Gerencial Mensal, 8. DRE por Centro de Custo e 9. DRE por Linha de Serviço.
A21: CAMPOS MÍNIMOS PARA NOVO CR
A22: ID título, Cliente, Emissão, Vencimento, Valor e Tipo receita DRE são o mínimo para a DRE funcionar.
A23: Recebimento, Valor recebido e Status permitem fechar o caixa e a carteira.
A24: Cliente mestre, Contrato/OS, Serviço e Centro de resultado dão rastreabilidade ERP.
A28: CAMPOS MÍNIMOS PARA NOVO CP
... A31: A classificação DRE agora é automática por grupo/natureza via 17. Mapa DRE CP; revise quando aparecer "Revisar".

Sheet Catálogo de Serviços
A1: CATÁLOGO DE SERVIÇOS — BASE DE PREÇO PISO EXTRAÍDA DA PLANILHA ORIGINAL
A2: Use este catálogo como referência comercial no bloco 1. Valores baseados na aba "Tabela de Serviços" da planilha enviada.
A4: Serviço | B4: Horas estimadas | C4: Km base | D4: Retrabalho | E4: Piso base | F4: Piso c/ margem 20% | G4: Fator risco ART
A5: PCMSO (até 10 funcionários) | B5: 12 | C5: 50 | D5: 0.12 | E5: 4558 | F5: 5890 | G5: 15–30%
A6: PCMSO (11–30 funcionários) | B6: 16 | C6: 50 | D6: 0.14 | E6: 6381 | F6: 8246 | G6: 15–30%
A7: PCMSO (31–100 funcionários) | B7: 22 | C7: 60 | D7: 0.15 | E7: 8660 | F7: 11191 | G7: 15–30%
A8: PGR — Grau I (até 10 func.) | B8: 14 | C8: 70 | D8: 0.15 | E8: 5557 | F8: 7280 | G8: 15–30%
A9: PGR — Grau II (até 10 func.) | B9: 16 | C9: 70 | D9: 0.16 | E9: 6668 | F9: 8736 | G9: 15–30%
A10: PGR — Grau III (até 10 func.) | B10: 20 | C10: 80 | D10: 0.18 | E10: 8057 | F10: 10556 | G10: 15–30%
A11: LTCAT — físicos simples | B11: 18 | C11: 80 | D11: 0.18 | E11: 7465 | F11: 9870 | G11: 15–30%
A12: LTCAT — físicos + químicos | B12: 24 | C12: 80 | D12: 0.2 | E12: 9332 | F12: 13318 | G12: 15–30%
A13: Laudo insalub. — 1 agente | B13: 12 | C13: 60 | D13: 0.2 | E13: 5104 | F13: 6620 | G13: 15–30%
A14: Laudo insalub. — 2–3 agentes | B14: 16 | C14: 60 | D14: 0.22 | E14: 6380 | F14: 8276 | G14: 15–30%
A15: Treinamento NR — até 20 pessoas | B15: 8 | C15: 50 | D15: 0.05 | E15: 2915 | F15: 3680 | G15: +30% noturno
A16: Treinamento NR12 / NR10 | B16: 12 | C16: 50 | D16: 0.08 | E16: 4372 | F16: 5520 | G16: +30%
... A20: Perícia — c/ laudos compl. | B20: 24 | C20: 60 | D20: 0.2 | E20: 9817 | F20: 11688 | G20: +R$1.400/diária
A21: REGRAS DE APLICAÇÃO RÁPIDA
A22: Preço piso | B22: Chão absoluto. Nenhuma proposta pode sair abaixo deste valor. É o custo real + overhead + tributo + margem 20%.
A23: Preço alvo | B23: Deve ficar entre 120% e 150% do piso para garantir EBITDA saudável e margem para negociação.
A24: Renovação PGR | B24: Desconto máximo de 20% sobre o piso — base já levantada, menos horas necessárias.
A25: Deslocamento | B25: Até 30km de Uberlândia: incluso. 31–100km: +R$1,20/km. Acima de 100km: diária técnica de R$1.400.
A26: Urgência | B26: 7–14 dias: +15%. Menos de 7 dias: +30%. Menos de 48h: +50% ou recusa.
A27: Múltiplas unidades | B27: 2ª e 3ª unidade: fator 0,85 por unidade. 4ª em diante: orçamento específico.

Sheet Diagnóstico 5 Blocos
A1: HIGILABOR — DIAGNÓSTICO CONSOLIDADO DOS 5 BLOCOS
A2: Leitura técnica consolidada após carga do CR/CP de março e inclusão da base de custos do CSV da planilha de precificação.
A4: STATUS DOS 5 BLOCOS
A5: Bloco | B5: Status | C5: O que já existe na planilha enviada | D5: O que falta para gestão real | E5: Próxima base necessária | F5: Prioridade | G5: Leitura executiva
A6: 1. Receita | B6: PARCIAL | C6: Catálogo de serviços e política de preço piso; ainda sem histórico comercial completo por venda. | D6: Histórico real por cliente, data, preço fechado, quantidade, recorrência e desconto. | E6: Planilha/relatório comercial com vendas emitidas. | F6: ALTA | G6: A base econômica está pronta, mas o transacional de vendas ainda precisa ser consolidado.
A7: 2. Contas a Receber | B7: OPERACIONAL | C7: Carteira de março lançada, com títulos, vencimentos, recebimentos, abertos e aging. | D7: Ampliar para histórico contínuo e vincular cada título à venda-mãe. | E7: CR mensal recorrente + chave de venda/pedido. | F7: ALTA | G7: Já mede conversão em caixa; falta histórico e reconciliação com vendas.
A8: 3. Contas a Pagar | B8: OPERACIONAL | C8: CP de março lançado, reconciliado com a base de custos da precificação e agora classificado por centro de custo real e grupo gerencial. | D8: Adicionar datas reais de pagamento e histórico mensal contínuo para sair do retrato pontual. | E8: CP mensal recorrente com data efetiva de pagamento. | F8: ALTA | G8: O bloco já sustenta leitura de saída, caixa e estrutura por grupo de custo.
A9: 4. Fluxo de Caixa | B9: OPERACIONAL | C9: Fluxo mensal já calculado a partir do CR e do CP lançados. | D9: Passar do recorte mensal para rotina semanal e saldo inicial real de caixa. | E9: Saldo inicial + movimentação bancária + CR/CP contínuos. | F9: CRÍTICA | G9: Já mostra pressão de caixa; próximo salto é granularidade semanal e projeção contínua.
A10: 5. Indicadores | B10: PARCIAL | C10: Painel já consolida CR, CP, fluxo e agora a estrutura base do CSV (UEP, custo estrutural e rateio). | D10: Completar com KPIs de receita real, margem por serviço, PMR e concentração por cliente. | E10: Bloco 1 completo + histórico de operações. | F10: ALTA | G10: O painel já é gerencial; falta fechar a camada comercial para virar painel diretivo completo.
A13: BASES INCORPORADAS: Mar/2026 | CR 35.862,39 | CP 38.149,72 | Realizado do mês (recebido-pago): -12.442,03.
A14: BASES INCORPORADAS: Mar/2026 | CR 35.862,39 | CP 38.149,72 | Realizado do mês (recebido-pago): -12.442,03 | CP classificado por grupo gerencial. | B14: 35862.39 | C14: Recebido 25.338,89 | Aberto 10.523,50 | D14: Bloco 2 alimentado | E14: PDF CR | F14: ALTA | G14: Carteira, recebimento e aging já mensuráveis.
A15: Contas a pagar | B15: 38149.72 | C15: Pago 37.780,92 | Aberto 368,80 | D15: Bloco 3 alimentado | E15: PDF CP | F15: ALTA | G15: Saídas e obrigações já estruturadas.
A16: Fluxo de caixa | B16: -12442.03 | C16: Realizado do mês | D16: Bloco 4 operacional | E16: CR + CP | F16: ALTA | G16: Houve aperto de caixa relevante em março.
A17: Receita | C17: Continua parcial | D17: CR mostra títulos, não vendas consolidadas | E17: Base comercial | F17: CRÍTICA | G17: Sem relatório comercial, bloco 1 fica incompleto.
A18: EBITDA mínimo alvo | B18: 0.2 | C18: A política comercial parte de um alvo de margem operacional.
A19: Preço piso PCMSO padrão | B19: 6104.42 | C19: Valor observado na calculadora para o serviço selecionado no arquivo original.

Sheet 1. Receita
A1: 1. RECEITA — LANÇAMENTO COMERCIAL / FATURAMENTO
A2: Lançe cada venda/proposta fechada. O preço piso de referência é puxado do catálogo de serviços.
A4: BASE OPERACIONAL
A5: Data venda | B5: Competência | C5: Cliente | D5: Serviço | E5: Qtd | F5: Preço unitário cotado | G5: Preço piso ref. | H5: Receita bruta | I5: Gap unit. vs piso | J5: Status | K5: Observação
B7: =IF(A7="","",DATE(YEAR(A7),MONTH(A7),1)) | G7: =IFERROR(VLOOKUP(D7,'Catálogo de Serviços'!$A$5:$F$100,6,FALSE),0) | H7: =IFERROR(E7*F7,0) | I7: =IFERROR(F7-G7,0)
B8: =IF(A8="","",DATE(YEAR(A8),MONTH(A8),1)) | G8: =IFERROR(VLOOKUP(D8,'Catálogo de Serviços'!$A$5:$F$100,6,FALSE),0) | H8: =IFERROR(E8*F8,0) | I8: =IFERROR(F8-G8,0)
B9: =IF(A9="","",DATE(YEAR(A9),MONTH(A9),1)) | G9: =IFERROR(VLOOKUP(D9,'Catálogo de Serviços'!$A$5:$F$100,6,FALSE),0) | H9: =IFERROR(E9*F9,0) | I9: =IFERROR(F9-G9,0)
B10: =IF(A10="","",DATE(YEAR(A10),MONTH(A10),1)) | G10: =IFERROR(VLOOKUP(D10,'Catálogo de Serviços'!$A$5:$F$100,6,FALSE),0) | H10: =IFERROR(E10*F10,0) | I10: =IFERROR(F10-G10,0)
B11: =IF(A11="","",DATE(YEAR(A11),MONTH(A11),1)) | G11: =IFERROR(VLOOKUP(D11,'Catálogo de Serviços'!$A$5:$F$100,6,FALSE),0) | H11: =IFERROR(E11*F11,0) | I11: =IFERROR(F11-G11,0)
B12: =IF(A12="","",DATE(YEAR(A12),MONTH(A12),1)) | G12: =IFERROR(VLOOKUP(D12,'Catálogo de Serviços'!$A$5:$F$100,6,FALSE),0) | H12: =IFERROR(E12*F12,0) | I12: =IFERROR(F12-G12,0)
B13: =IF(A13="","",DATE(YEAR(A13),MONTH(A13),1)) | G13: =IFERROR(VLOOKUP(D13,'Catálogo de Serviços'!$A$5:$F$100,6,FALSE),0) | H13: =IFERROR(E13*F13,0) | I13: =IFERROR(F13-G13,0)
B14: =IF(A14="","",DATE(YEAR(A14),MONTH(A14),1)) | G14: =IFERROR(VLOOKUP(D14,'Catálogo de Serviços'!$A$5:$F$100,6,FALSE),0) | H14: =IFERROR(E14*F14,0) | I14: =IFERROR(F14-G14,0)
B15: =IF(A15="","",DATE(YEAR(A15),MONTH(A15),1)) | G15: =IFERROR(VLOOKUP(D15,'Catálogo de Serviços'!$A$5:$F$100,6,FALSE),0) | H15: =IFERROR(E15*F15,0) | I15: =IFERROR(F15-G15,0)
B16: =IF(A16="","",DATE(YEAR(A16),MONTH(A16),1)) | G16: =IFERROR(VLOOKUP(D16,'Catálogo de Serviços'!$A$5:$F$100,6,FALSE),0) | H16: =IFERROR(E16*F16,0) | I16: =IFERROR(F16-G16,0)
B17: =IF(A17="","",DATE(YEAR(A17),MONTH(A17),1)) | G17: =IFERROR(VLOOKUP(D17,'Catálogo de Serviços'!$A$5:$F$100,6,FALSE),0) | H17: =IFERROR(E17*F17,0) | I17: =IFERROR(F17-G17,0)
B18: =IF(A18="","",DATE(YEAR(A18),MONTH(A18),1)) | G18: =IFERROR(VLOOKUP(D18,'Catálogo de Serviços'!$A$5:$F$100,6,FALSE),0) | H18: =IFERROR(E18*F18,0) | I18: =IFERROR(F18-G18,0)
... B1000: =IF(A1000="","",DATE(YEAR(A1000),MONTH(A1000),1)) | G1000: =IFERROR(VLOOKUP(D1000,'Catálogo de Serviços'!$A$5:$F$100,6,FALSE),0) | H1000: =IFERROR(E1000*F1000,0) | I1000: =IFERROR(F1000-G1000,0)
A1001: Bloco 1 continua parcial: CR mensal mostra títulos, não vendas consolidadas. Use relatório de vendas/pedidos.
A1003: RESUMO DO BLOCO 1
A1004: Vendas lançadas | B1004: =COUNTIF(C7:C1000,"<>")
A1005: Receita bruta | B1005: =SUM(H7:H1000)
A1006: Ticket médio | B1006: =IFERROR(B1005/B1004,0)
A1007: Gap médio unitário | B1007: =IFERROR(AVERAGE(I7:I1000),0)

Sheet 2. Contas a Receber
A1: 2. CONTAS A RECEBER — CARTEIRA DE TÍTULOS
A2: Cada linha representa um título/parcela. Agora o CR também está amarrado a cliente mestre, contrato/OS, serviço e centro de resultado.
A4: Data-base da análise | B4: =EOMONTH('0. Como Alimentar'!$B$7,0)
A6: BASE OPERACIONAL
A7: ID título | B7: ID venda | C7: Cliente | D7: Emissão | E7: Vencimento | F7: Recebimento | G7: Parcela | H7: Valor | I7: Valor recebido | J7: Status | K7: Dias atraso | L7: Faixa aging | M7: Observação | N7: Competência gerencial | O7: Tipo receita DRE | P7: Linha de serviço inferida | Q7: Centro de resultado | R7: Critério de classificação | S7: Cliente mestre | T7: Unidade / escopo | U7: Chave contrato/OS | V7: Contrato/OS ID | W7: Tipo vínculo ERP | X7: Cliente ID | Y7: Serviço ID | Z7: Serviço padronizado | AA7: Linha DRE rastreável | AB7: Centro de resultado rastreável | AC7: Parcela rastreada | AD7: Status rastreabilidade | AE7: Nota de rastreio
A8: CR-001 | B8: NIVALMAG - MATRIZ | C8: NIVALMAG - MATRIZ | D8: 46086 | E8: 46086 | F8: 46087 | H8: 1348 | I8: 1348 | J8: Recebido | K8: =IF(J8="","",IF(OR(J8="Recebido",F8=""),MAX(0,F8-E8),MAX(0,$B$4-E8))) | L8: =IF(K8="","",IF(K8=0,"Em dia",IF(K8<=30,"1-30 dias",IF(K8<=60,"31-60 dias",IF(K8<=90,"61-90 dias",">90 dias"))))) | M8: Origem: CR mar/2026. Tipo original: Fixo. Doc/NF: 83. | N8: 46082 | O8: Receita recorrente | P8: =IF(C8="","",IF(ISNUMBER(SEARCH("PCMSO",C8)),"PCMSO",IF(OR(ISNUMBER(SEARCH("E-SOCIAL",C8)),ISNUMBER(SEARCH("PSICOSOCIAL",C8))),"eSocial / Psicossocial",IF(O8="Receita recorrente","Carteira recorrente","Projetos / Laudos / Avulsos")))) | Q8: =IF(P8="","",IF(P8="Carteira recorrente","Operação recorrente",IF(P8="PCMSO","Projetos PCMSO",IF(P8="eSocial / Psicossocial","Projetos eSocial/Psicossocial","Projetos / Laudos / Avulsos")))) | R8: =IF(C8="","",IF(ISNUMBER(SEARCH("PCMSO",C8)),"Título com PCMSO no nome",IF(OR(ISNUMBER(SEARCH("E-SOCIAL",C8)),ISNUMBER(SEARCH("PSICOSOCIAL",C8))),"Título com eSocial/Psicossocial no nome",IF(O8="Receita recorrente","Tipo DRE recorrente","Extra sem palavra-chave específica")))) | S8: =IFERROR(VLOOKUP($A8,'13. Mapa Títulos-Receita'!$A$8:$P$1000,4,FALSE),"") | T8: =IFERROR(VLOOKUP($A8,'13. Mapa Títulos-Receita'!$A$8:$P$1000,5,FALSE),"") | U8: =IFERROR(VLOOKUP($A8,'13. Mapa Títulos-Receita'!$A$8:$P$1000,6,FALSE),"") | V8: =IFERROR(VLOOKUP($A8,'13. Mapa Títulos-Receita'!$A$8:$P$1000,7,FALSE),"") | W8: =IFERROR(VLOOKUP($A8,'13. Mapa Títulos-Receita'!$A$8:$P$1000,8,FALSE),"") | X8: =IFERROR(VLOOKUP($A8,'13. Mapa Títulos-Receita'!$A$8:$P$1000,9,FALSE),"") | Y8: =IFERROR(VLOOKUP($A8,'13. Mapa Títulos-Receita'!$A$8:$P$1000,10,FALSE),"") | Z8: =IFERROR(VLOOKUP($A8,'13. Mapa Títulos-Receita'!$A$8:$P$1000,11,FALSE),"") | AA8: =IFERROR(VLOOKUP($A8,'13. Mapa Títulos-Receita'!$A$8:$P$1000,12,FALSE),"") | AB8: =IFERROR(VLOOKUP($A8,'13. Mapa Títulos-Receita'!$A$8:$P$1000,13,FALSE),"") | AC8: =IFERROR(VLOOKUP($A8,'13. Mapa Títulos-Receita'!$A$8:$P$1000,14,FALSE),"") | AD8: =IFERROR(VLOOKUP($A8,'13. Mapa Títulos-Receita'!$A$8:$P$1000,15,FALSE),"") | AE8: =IFERROR(VLOOKUP($A8,'13. Mapa Títulos-Receita'!$A$8:$P$1000,16,FALSE),"")
A9: CR-002 | B9: NIVALMAG - FAZENDA | C9: NIVALMAG - FAZENDA | D9: 46086 | E9: 46086 | F9: 46087 | H9: 284 | I9: 284 | J9: Recebido | K9: =IF(J9="","",IF(OR(J9="Recebido",F9=""),MAX(0,F9-E9),MAX(0,$B$4-E9))) | L9: =IF(K9="","",IF(K9=0,"Em dia",IF(K9<=30,"1-30 dias",IF(K9<=60,"31-60 dias",IF(K9<=90,"61-90 dias",">90 dias"))))) | M9: Origem: CR mar/2026. Tipo original: Fixo. Doc/NF: 84. | N9: 46082 | O9: Receita recorrente | P9: =IF(C9="","",IF(ISNUMBER(SEARCH("PCMSO",C9)),"PCMSO",IF(OR(ISNUMBER(SEARCH("E-SOCIAL",C9)),ISNUMBER(SEARCH("PSICOSOCIAL",C9))),"eSocial / Psicossocial",IF(O9="Receita recorrente","Carteira recorrente","Projetos / Laudos / Avulsos")))) | Q9: =IF(P9="","",IF(P9="Carteira recorrente","Operação recorrente",IF(P9="PCMSO","Projetos PCMSO",IF(P9="eSocial / Psicossocial","Projetos eSocial/Psicossocial","Projetos / Laudos / Avulsos")))) | R9: =IF(C9="","",IF(ISNUMBER(SEARCH("PCMSO",C9)),"Título com PCMSO no nome",IF(OR(ISNUMBER(SEARCH("E-SOCIAL",C9)),ISNUMBER(SEARCH("PSICOSOCIAL",C9))),"Título com eSocial/Psicossocial no nome",IF(O9="Receita recorrente","Tipo DRE recorrente","Extra sem palavra-chave específica")))) | S9: =IFERROR(VLOOKUP($A9,'13. Mapa Títulos-Receita'!$A$8:$P$1000,4,FALSE),"") | T9: =IFERROR(VLOOKUP($A9,'13. Mapa Títulos-Receita'!$A$8:$P$1000,5,FALSE),"") | U9: =IFERROR(VLOOKUP($A9,'13. Mapa Títulos-Receita'!$A$8:$P$1000,6,FALSE),"") | V9: =IFERROR(VLOOKUP($A9,'13. Mapa Títulos-Receita'!$A$8:$P$1000,7,FALSE),"") | W9: =IFERROR(VLOOKUP($A9,'13. Mapa Títulos-Receita'!$A$8:$P$1000,8,FALSE),"") | X9: =IFERROR(VLOOKUP($A9,'13. Mapa Títulos-Receita'!$A$8:$P$1000,9,FALSE),"") | Y9: =IFERROR(VLOOKUP($A9,'13. Mapa Títulos-Receita'!$A$8:$P$1000,10,FALSE),"") | Z9: =IFERROR(VLOOKUP($A9,'13. Mapa Títulos-Receita'!$A$8:$P$1000,11,FALSE),"") | AA9: =IFERROR(VLOOKUP($A9,'13. Mapa Títulos-Receita'!$A$8:$P$1000,12,FALSE),"") | AB9: =IFERROR(VLOOKUP($A9,'13. Mapa Títulos-Receita'!$A$8:$P$1000,13,FALSE),"") | AC9: =IFERROR(VLOOKUP($A9,'13. Mapa Títulos-Receita'!$A$8:$P$1000,14,FALSE),"") | AD9: =IFERROR(VLOOKUP($A9,'13. Mapa Títulos-Receita'!$A$8:$P$1000,15,FALSE),"") | AE9: =IFERROR(VLOOKUP($A9,'13. Mapa Títulos-Receita'!$A$8:$P$1000,16,FALSE),"")
A10: CR-003 | B10: SONDOTEC | C10: SONDOTEC | D10: 46086 | E10: 46086 | F10: 46087 | H10: 960 | I10: 960 | J10: Recebido | K10: =IF(J10="","",IF(OR(J10="Recebido",F10=""),MAX(0,F10-E10),MAX(0,$B$4-E10))) | L10: =IF(K10="","",IF(K10=0,"Em dia",IF(K10<=30,"1-30 dias",IF(K10<=60,"31-60 dias",IF(K10<=90,"61-90 dias",">90 dias"))))) | M10: Origem: CR mar/2026. Tipo original: Fixo. Doc/NF: 81. | N10: 46082 | O10: Receita recorrente | P10: =IF(C10="","",IF(ISNUMBER(SEARCH("PCMSO",C10)),"PCMSO",IF(OR(ISNUMBER(SEARCH("E-SOCIAL",C10)),ISNUMBER(SEARCH("PSICOSOCIAL",C10))),"eSocial / Psicossocial",IF(O10="Receita recorrente","Carteira recorrente","Projetos / Laudos / Avulsos")))) | Q10: =IF(P10="","",IF(P10="Carteira recorrente","Operação recorrente",IF(P10="PCMSO","Projetos PCMSO",IF(P10="eSocial / Psicossocial","Projetos eSocial/Psicossocial","Projetos / Laudos / Avulsos")))) | R10: =IF(C10="","",IF(ISNUMBER(SEARCH("PCMSO",C10)),"Título com PCMSO no nome",IF(OR(ISNUMBER(SEARCH("E-SOCIAL",C10)),ISNUMBER(SEARCH("PSICOSOCIAL",C10))),"Título com eSocial/Psicossocial no nome",IF(O10="Receita recorrente","Tipo DRE recorrente","Extra sem palavra-chave específica")))) | S10: =IFERROR(VLOOKUP($A10,'13. Mapa Títulos-Receita'!$A$8:$P$1000,4,FALSE),"") | T10: =IFERROR(VLOOKUP($A10,'13. Mapa Títulos-Receita'!$A$8:$P$1000,5,FALSE),"") | U10: =IFERROR(VLOOKUP($A10,'13. Mapa Títulos-Receita'!$A$8:$P$1000,6,FALSE),"") | V10: =IFERROR(VLOOKUP($A10,'13. Mapa Títulos-Receita'!$A$8:$P$1000,7,FALSE),"") | W10: =IFERROR(VLOOKUP($A10,'13. Mapa Títulos-Receita'!$A$8:$P$1000,8,FALSE),"") | X10: =IFERROR(VLOOKUP($A10,'13. Mapa Títulos-Receita'!$A$8:$P$1000,9,FALSE),"") | Y10: =IFERROR(VLOOKUP($A10,'13. Mapa Títulos-Receita'!$A$8:$P$1000,10,FALSE),"") | Z10: =IFERROR(VLOOKUP($A10,'13. Mapa Títulos-Receita'!$A$8:$P$1000,11,FALSE),"") | AA10: =IFERROR(VLOOKUP($A10,'13. Mapa Títulos-Receita'!$A$8:$P$1000,12,FALSE),"") | AB10: =IFERROR(VLOOKUP($A10,'13. Mapa Títulos-Receita'!$A$8:$P$1000,13,FALSE),"") | AC10: =IFERROR(VLOOKUP($A10,'13. Mapa Títulos-Receita'!$A$8:$P$1000,14,FALSE),"") | AD10: =IFERROR(VLOOKUP($A10,'13. Mapa Títulos-Receita'!$A$8:$P$1000,15,FALSE),"") | AE10: =IFERROR(VLOOKUP($A10,'13. Mapa Títulos-Receita'!$A$8:$P$1000,16,FALSE),"")
A11: CR-004 | B11: TRIÂNGULO SERVIÇOS | C11: TRIÂNGULO SERVIÇOS | D11: 46086 | E11: 46086 | F11: 46087 | H11: 477 | I11: 477 | J11: Recebido | K11: =IF(J11="","",IF(OR(J11="Recebido",F11=""),MAX(0,F11-E11),MAX(0,$B$4-E11))) | L11: =IF(K11="","",IF(K11=0,"Em dia",IF(K11<=30,"1-30 dias",IF(K11<=60,"31-60 dias",IF(K11<=90,"61-90 dias",">90 dias"))))) | M11: Origem: CR mar/2026. Tipo original: Fixo. Doc/NF: 80. | N11: 46082 | O11: Receita recorrente | P11: =IF(C11="","",IF(ISNUMBER(SEARCH("PCMSO",C11)),"PCMSO",IF(OR(ISNUMBER(SEARCH("E-SOCIAL",C11)),ISNUMBER(SEARCH("PSICOSOCIAL",C11))),"eSocial / Psicossocial",IF(O11="Receita recorrente","Carteira recorrente","Projetos / Laudos / Avulsos")))) | Q11: =IF(P11="","",IF(P11="Carteira recorrente","Operação recorrente",IF(P11="PCMSO","Projetos PCMSO",IF(P11="eSocial / Psicossocial","Projetos eSocial/Psicossocial","Projetos / Laudos / Avulsos")))) | R11: =IF(C11="","",IF(ISNUMBER(SEARCH("PCMSO",C11)),"Título com PCMSO no nome",IF(OR(ISNUMBER(SEARCH("E-SOCIAL",C11)),ISNUMBER(SEARCH("PSICOSOCIAL",C11))),"Título com eSocial/Psicossocial no nome",IF(O11="Receita recorrente","Tipo DRE recorrente","Extra sem palavra-chave específica")))) | S11: =IFERROR(VLOOKUP($A11,'13. Mapa Títulos-Receita'!$A$8:$P$1000,4,FALSE),"") | T11: =IFERROR(VLOOKUP($A11,'13. Mapa Títulos-Receita'!$A$8:$P$1000,5,FALSE),"") | U11: =IFERROR(VLOOKUP($A11,'13. Mapa Títulos-Receita'!$A$8:$P$1000,6,FALSE),"") | V11: =IFERROR(VLOOKUP($A11,'13. Mapa Títulos-Receita'!$A$8:$P$1000,7,FALSE),"") | W11: =IFERROR(VLOOKUP($A11,'13. Mapa Títulos-Receita'!$A$8:$P$1000,8,FALSE),"") | X11: =IFERROR(VLOOKUP($A11,'13. Mapa Títulos-Receita'!$A$8:$P$1000,9,FALSE),"") | Y11: =IFERROR(VLOOKUP($A11,'13. Mapa Títulos-Receita'!$A$8:$P$1000,10,FALSE),"") | Z11: =IFERROR(VLOOKUP($A11,'13. Mapa Títulos-Receita'!$A$8:$P$1000,11,FALSE),"") | AA11: =IFERROR(VLOOKUP($A11,'13. Mapa Títulos-Receita'!$A$8:$P$1000,12,FALSE),"") | AB11: =IFERROR(VLOOKUP($A11,'13. Mapa Títulos-Receita'!$A$8:$P$1000,13,FALSE),"") | AC11: =IFERROR(VLOOKUP($A11,'13. Mapa Títulos-Receita'!$A$8:$P$1000,14,FALSE),"") | AD11: =IFERROR(VLOOKUP($A11,'13. Mapa Títulos-Receita'!$A$8:$P$1000,15,FALSE),"") | AE11: =IFERROR(VLOOKUP($A11,'13. Mapa Títulos-Receita'!$A$8:$P$1000,16,FALSE),"")
A12: CR-005 | B12: CONTROLER | C12: CONTROLER | D12: 46086 | E12: 46086 | F12: 46098 | H12: 374 | I12: 374 | J12: Recebido | K12: =IF(J12="","",IF(OR(J12="Recebido",F12=""),MAX(0,F12-E12),MAX(0,$B$4-E12))) | L12: =IF(K12="","",IF(K12=0,"Em dia",IF(K12<=30,"1-30 dias",IF(K12<=60,"31-60 dias",IF(K12<=90,"61-90 dias",">90 dias"))))) | M12: Origem: CR mar/2026. Tipo original: Fixo. Doc/NF: 82. | N12: 46082 | O12: Receita recorrente | P12: =IF(C12="","",IF(ISNUMBER(SEARCH("PCMSO",C12)),"PCMSO",IF(OR(ISNUMBER(SEARCH("E-SOCIAL",C12)),ISNUMBER(SEARCH("PSICOSOCIAL",C12))),"eSocial / Psicossocial",IF(O12="Receita recorrente","Carteira recorrente","Projetos / Laudos / Avulsos")))) | Q12: =IF(P12="","",IF(P12="Carteira recorrente","Operação recorrente",IF(P12="PCMSO","Projetos PCMSO",IF(P12="eSocial / Psicossocial","Projetos eSocial/Psicossocial","Projetos / Laudos / Avulsos")))) | R12: =IF(C12="","",IF(ISNUMBER(SEARCH("PCMSO",C12)),"Título com PCMSO no nome",IF(OR(ISNUMBER(SEARCH("E-SOCIAL",C12)),ISNUMBER(SEARCH("PSICOSOCIAL",C12))),"Título com eSocial/Psicossocial no nome",IF(O12="Receita recorrente","Tipo DRE recorrente","Extra sem palavra-chave específica")))) | S12: =IFERROR(VLOOKUP($A12,'13. Mapa Títulos-Receita'!$A$8:$P$1000,4,FALSE),"") | T12: =IFERROR(VLOOKUP($A12,'13. Mapa Títulos-Receita'!$A$8:$P$1000,5,FALSE),"") | U12: =IFERROR(VLOOKUP($A12,'13. Mapa Títulos-Receita'!$A$8:$P$1000,6,FALSE),"") | V12: =IFERROR(VLOOKUP($A12,'13. Mapa Títulos-Receita'!$A$8:$P$1000,7,FALSE),"") | W12: =IFERROR(VLOOKUP($A12,'13. Mapa Títulos-Receita'!$A$8:$P$1000,8,FALSE),"") | X12: =IFERROR(VLOOKUP($A12,'13. Mapa Títulos-Receita'!$A$8:$P$1000,9,FALSE),"") | Y12: =IFERROR(VLOOKUP($A12,'13. Mapa Títulos-Receita'!$A$8:$P$1000,10,FALSE),"") | Z12: =IFERROR(VLOOKUP($A12,'13. Mapa Títulos-Receita'!$A$8:$P$1000,11,FALSE),"") | AA12: =IFERROR(VLOOKUP($A12,'13. Mapa Títulos-Receita'!$A$8:$P$1000,12,FALSE),"") | AB12: =IFERROR(VLOOKUP($A12,'13. Mapa Títulos-Receita'!$A$8:$P$1000,13,FALSE),"") | AC12: =IFERROR(VLOOKUP($A12,'13. Mapa Títulos-Receita'!$A$8:$P$1000,14,FALSE),"") | AD12: =IFERROR(VLOOKUP($A12,'13. Mapa Títulos-Receita'!$A$8:$P$1000,15,FALSE),"") | AE12: =IFERROR(VLOOKUP($A12,'13. Mapa Títulos-Receita'!$A$8:$P$1000,16,FALSE),"")
A13: CR-006 | B13: SANTA CASA MT ALEGRE | C13: SANTA CASA MT ALEGRE | D13: 46086 | E13: 46086 | F13: 46085 | H13: 1588 | I13: 1588 | J13: Recebido | K13: =IF(J13="","",IF(OR(J13="Recebido",F13=""),MAX(0,F13-E13),MAX(0,$B$4-E13))) | L13: =IF(K13="","",IF(K13=0,"Em dia",IF(K13<=30,"1-30 dias",IF(K13<=60,"31-60 dias",IF(K13<=90,"61-90 dias",">90 dias"))))) | M13: Origem: CR mar/2026. Tipo original: Fixo. Doc/NF: 92. | N13: 46082 | O13: Receita recorrente | P13: =IF(C13="","",IF(ISNUMBER(SEARCH("PCMSO",C13)),"PCMSO",IF(OR(ISNUMBER(SEARCH("E-SOCIAL",C13)),ISNUMBER(SEARCH("PSICOSOCIAL",C13))),"eSocial / Psicossocial",IF(O13="Receita recorrente","Carteira recorrente","Projetos / Laudos / Avulsos")))) | Q13: =IF(P13="","",IF(P13="Carteira recorrente","Operação recorrente",IF(P13="PCMSO","Projetos PCMSO",IF(P13="eSocial / Psicossocial","Projetos eSocial/Psicossocial","Projetos / Laudos / Avulsos")))) | R13: =IF(C13="","",IF(ISNUMBER(SEARCH("PCMSO",C13)),"Título com PCMSO no nome",IF(OR(ISNUMBER(SEARCH("E-SOCIAL",C13)),ISNUMBER(SEARCH("PSICOSOCIAL",C13))),"Título com eSocial/Psicossocial no nome",IF(O13="Receita recorrente","Tipo DRE recorrente","Extra sem palavra-chave específica")))) | S13: =IFERROR(VLOOKUP($A13,'13. Mapa Títulos-Receita'!$A$8:$P$1000,4,FALSE),"") | T13: =IFERROR(VLOOKUP($A13,'13. Mapa Títulos-Receita'!$A$8:$P$1000,5,FALSE),"") | U13: =IFERROR(VLOOKUP($A13,'13. Mapa Títulos-Receita'!$A$8:$P$1000,6,FALSE),"") | V13: =IFERROR(VLOOKUP($A13,'13. Mapa Títulos-Receita'!$A$8:$P$1000,7,FALSE),"") | W13: =IFERROR(VLOOKUP($A13,'13. Mapa Títulos-Receita'!$A$8:$P$1000,8,FALSE),"") | X13: =IFERROR(VLOOKUP($A13,'13. Mapa Títulos-Receita'!$A$8:$P$1000,9,FALSE),"") | Y13: =IFERROR(VLOOKUP($A13,'13. Mapa Títulos-Receita'!$A$8:$P$1000,10,FALSE),"") | Z13: =IFERROR(VLOOKUP($A13,'13. Mapa Títulos-Receita'!$A$8:$P$1000,11,FALSE),"") | AA13: =IFERROR(VLOOKUP($A13,'13. Mapa Títulos-Receita'!$A$8:$P$1000,12,FALSE),"") | AB13: =IFERROR(VLOOKUP($A13,'13. Mapa Títulos-Receita'!$A$8:$P$1000,13,FALSE),"") | AC13: =IFERROR(VLOOKUP($A13,'13. Mapa Títulos-Receita'!$A$8:$P$1000,14,FALSE),"") | AD13: =IFERROR(VLOOKUP($A13,'13. Mapa Títulos-Receita'!$A$8:$P$1000,15,FALSE),"") | AE13: =IFERROR(VLOOKUP($A13,'13. Mapa Títulos-Receita'!$A$8:$P$1000,16,FALSE),"")
A14: CR-007 | B14: FAZENDA SANTA LUCIA | C14: FAZENDA SANTA LUCIA | D14: 46086 | E14: 46086 | F14: 46087 | H14: 3166 | I14: 3166 | J14: Recebido | K14: =IF(J14="","",IF(OR(J14="Recebido",F14=""),MAX(0,F14-E14),MAX(0,$B$4-E14))) | L14: =IF(K14="","",IF(K14=0,"Em dia",IF(K14<=30,"1-30 dias",IF(K14<=60,"31-60 dias",IF(K14<=90,"61-90 dias",">90 dias"))))) | M14: Origem: CR mar/2026. Tipo original: Fixo. Doc/NF: 85. | N14: 46082 | O14: Receita recorrente | P14: =IF(C14="","",IF(ISNUMBER(SEARCH("PCMSO",C14)),"PCMSO",IF(OR(ISNUMBER(SEARCH("E-SOCIAL",C14)),ISNUMBER(SEARCH("PSICOSOCIAL",C14))),"eSocial / Psicossocial",IF(O14="Receita recorrente","Carteira recorrente","Projetos / Laudos / Avulsos")))) | Q14: =IF(P14="","",IF(P14="Carteira recorrente","Operação recorrente",IF(P14="PCMSO","Projetos PCMSO",IF(P14="eSocial / Psicossocial","Projetos eSocial/Psicossocial","Projetos / Laudos / Avulsos")))) | R14: =IF(C14="","",IF(ISNUMBER(SEARCH("PCMSO",C14)),"Título com PCMSO no nome",IF(OR(ISNUMBER(SEARCH("E-SOCIAL",C14)),ISNUMBER(SEARCH("PSICOSOCIAL",C14))),"Título com eSocial/Psicossocial no nome",IF(O14="Receita recorrente","Tipo DRE recorrente","Extra sem palavra-chave específica")))) | S14: =IFERROR(VLOOKUP($A14,'13. Mapa Títulos-Receita'!$A$8:$P$1000,4,FALSE),"") | T14: =IFERROR(VLOOKUP($A14,'13. Mapa Títulos-Receita'!$A$8:$P$1000,5,FALSE),"") | U14: =IFERROR(VLOOKUP($A14,'13. Mapa Títulos-Receita'!$A$8:$P$1000,6,FALSE),"") | V14: =IFERROR(VLOOKUP($A14,'13. Mapa Títulos-Receita'!$A$8:$P$1000,7,FALSE),"") | W14: =IFERROR(VLOOKUP($A14,'13. Mapa Títulos-Receita'!$A$8:$P$1000,8,FALSE),"") | X14: =IFERROR(VLOOKUP($A14,'13. Mapa Títulos-Receita'!$A$8:$P$1000,9,FALSE),"") | Y14: =IFERROR(VLOOKUP($A14,'13. Mapa Títulos-Receita'!$A$8:$P$1000,10,FALSE),"") | Z14: =IFERROR(VLOOKUP($A14,'13. Mapa Títulos-Receita'!$A$8:$P$1000,11,FALSE),"") | AA14: =IFERROR(VLOOKUP($A14,'13. Mapa Títulos-Receita'!$A$8:$P$1000,12,FALSE),"") | AB14: =IFERROR(VLOOKUP($A14,'13. Mapa Títulos-Receita'!$A$8:$P$1000,13,FALSE),"") | AC14: =IFERROR(VLOOKUP($A14,'13. Mapa Títulos-Receita'!$A$8:$P$1000,14,FALSE),"") | AD14: =IFERROR(VLOOKUP($A14,'13. Mapa Títulos-Receita'!$A$8:$P$1000,15,FALSE),"") | AE14: =IFERROR(VLOOKUP($A14,'13. Mapa Títulos-Receita'!$A$8:$P$1000,16,FALSE),"")
A15: CR-008 | B15: LGA MÁQUINAS | C15: LGA MÁQUINAS | D15: 46091 | E15: 46091 | F15: 46092 | H15: 210 | I15: 210 | J15: Recebido | K15: =IF(J15="","",IF(OR(J15="Recebido",F15=""),MAX(0,F15-E15),MAX(0,$B$4-E15))) | L15: =IF(K15="","",IF(K15=0,"Em dia",IF(K15<=30,"1-30 dias",IF(K15<=60,"31-60 dias",IF(K15<=90,"61-90 dias",">90 dias"))))) | M15: Origem: CR mar/2026. Tipo original: Fixo. Doc/NF: S/N. | N15: 46082 | O15: Receita recorrente | P15: =IF(C15="","",IF(ISNUMBER(SEARCH("PCMSO",C15)),"PCMSO",IF(OR(ISNUMBER(SEARCH("E-SOCIAL",C15)),ISNUMBER(SEARCH("PSICOSOCIAL",C15))),"eSocial / Psicossocial",IF(O15="Receita recorrente","Carteira recorrente","Projetos / Laudos / Avulsos")))) | Q15: =IF(P15="","",IF(P15="Carteira recorrente","Operação recorrente",IF(P15="PCMSO","Projetos PCMSO",IF(P15="eSocial / Psicossocial","Projetos eSocial/Psicossocial","Projetos / Laudos / Avulsos")))) | R15: =IF(C15="","",IF(ISNUMBER(SEARCH("PCMSO",C15)),"Título com PCMSO no nome",IF(OR(ISNUMBER(SEARCH("E-SOCIAL",C15)),ISNUMBER(SEARCH("PSICOSOCIAL",C15))),"Título com eSocial/Psicossocial no nome",IF(O15="Receita recorrente","Tipo DRE recorrente","Extra sem palavra-chave específica")))) | S15: =IFERROR(VLOOKUP($A15,'13. Mapa Títulos-Receita'!$A$8:$P$1000,4,FALSE),"") | T15: =IFERROR(VLOOKUP($A15,'13. Mapa Títulos-Receita'!$A$8:$P$1000,5,FALSE),"") | U15: =IFERROR(VLOOKUP($A15,'13. Mapa Títulos-Receita'!$A$8:$P$1000,6,FALSE),"") | V15: =IFERROR(VLOOKUP($A15,'13. Mapa Títulos-Receita'!$A$8:$P$1000,7,FALSE),"") | W15: =IFERROR(VLOOKUP($A15,'13. Mapa Títulos-Receita'!$A$8:$P$1000,8,FALSE),"") | X15: =IFERROR(VLOOKUP($A15,'13. Mapa Títulos-Receita'!$A$8:$P$1000,9,FALSE),"") | Y15: =IFERROR(VLOOKUP($A15,'13. Mapa Títulos-Receita'!$A$8:$P$1000,10,FALSE),"") | Z15: =IFERROR(VLOOKUP($A15,'13. Mapa Títulos-Receita'!$A$8:$P$1000,11,FALSE),"") | AA15: =IFERROR(VLOOKUP($A15,'13. Mapa Títulos-Receita'!$A$8:$P$1000,12,FALSE),"") | AB15: =IFERROR(VLOOKUP($A15,'13. Mapa Títulos-Receita'!$A$8:$P$1000,13,FALSE),"") | AC15: =IFERROR(VLOOKUP($A15,'13. Mapa Títulos-Receita'!$A$8:$P$1000,14,FALSE),"") | AD15: =IFERROR(VLOOKUP($A15,'13. Mapa Títulos-Receita'!$A$8:$P$1000,15,FALSE),"") | AE15: =IFERROR(VLOOKUP($A15,'13. Mapa Títulos-Receita'!$A$8:$P$1000,16,FALSE),"")
A16: CR-009 | B16: REPET | C16: REPET | D16: 46094 | E16: 46094 | F16: 46097 | H16: 1571.56 | I16: 1571.56 | J16: Recebido | K16: =IF(J16="","",IF(OR(J16="Recebido",F16=""),MAX(0,F16-E16),MAX(0,$B$4-E16))) | L16: =IF(K16="","",IF(K16=0,"Em dia",IF(K16<=30,"1-30 dias",IF(K16<=60,"31-60 dias",IF(K16<=90,"61-90 dias",">90 dias"))))) | M16: Origem: CR mar/2026. Tipo original: Fixo. Doc/NF: 109. | N16: 46082 | O16: Receita recorrente | P16: =IF(C16="","",IF(ISNUMBER(SEARCH("PCMSO",C16)),"PCMSO",IF(OR(ISNUMBER(SEARCH("E-SOCIAL",C16)),ISNUMBER(SEARCH("PSICOSOCIAL",C16))),"eSocial / Psicossocial",IF(O16="Receita recorrente","Carteira recorrente","Projetos / Laudos / Avulsos")))) | Q16: =IF(P16="","",IF(P16="Carteira recorrente","Operação recorrente",IF(P16="PCMSO","Projetos PCMSO",IF(P16="eSocial / Psicossocial","Projetos eSocial/Psicossocial","Projetos / Laudos / Avulsos")))) | R16: =IF(C16="","",IF(ISNUMBER(SEARCH("PCMSO",C16)),"Título com PCMSO no nome",IF(OR(ISNUMBER(SEARCH("E-SOCIAL",C16)),ISNUMBER(SEARCH("PSICOSOCIAL",C16))),"Título com eSocial/Psicossocial no nome",IF(O16="Receita recorrente","Tipo DRE recorrente","Extra sem palavra-chave específica")))) | S16: =IFERROR(VLOOKUP($A16,'13. Mapa Títulos-Receita'!$A$8:$P$1000,4,FALSE),"") | T16: =IFERROR(VLOOKUP($A16,'13. Mapa Títulos-Receita'!$A$8:$P$1000,5,FALSE),"") | U16: =IFERROR(VLOOKUP($A16,'13. Mapa Títulos-Receita'!$A$8:$P$1000,6,FALSE),"") | V16: =IFERROR(VLOOKUP($A16,'13. Mapa Títulos-Receita'!$A$8:$P$1000,7,FALSE),"") | W16: =IFERROR(VLOOKUP($A16,'13. Mapa Títulos-Receita'!$A$8:$P$1000,8,FALSE),"") | X16: =IFERROR(VLOOKUP($A16,'13. Mapa Títulos-Receita'!$A$8:$P$1000,9,FALSE),"") | Y16: =IFERROR(VLOOKUP($A16,'13. Mapa Títulos-Receita'!$A$8:$P$1000,10,FALSE),"") | Z16: =IFERROR(VLOOKUP($A16,'13. Mapa Títulos-Receita'!$A$8:$P$1000,11,FALSE),"") | AA16: =IFERROR(VLOOKUP($A16,'13. Mapa Títulos-Receita'!$A$8:$P$1000,12,FALSE),"") | AB16: =IFERROR(VLOOKUP($A16,'13. Mapa Títulos-Receita'!$A$8:$P$1000,13,FALSE),"") | AC16: =IFERROR(VLOOKUP($A16,'13. Mapa Títulos-Receita'!$A$8:$P$1000,14,FALSE),"") | AD16: =IFERROR(VLOOKUP($A16,'13. Mapa Títulos-Receita'!$A$8:$P$1000,15,FALSE),"") | AE16: =IFERROR(VLOOKUP($A16,'13. Mapa Títulos-Receita'!$A$8:$P$1000,16,FALSE),"")
A17: CR-010 | B17: SKAP KAP | C17: SKAP KAP | D17: 46086 | E17: 46086 | F17: 46083 | H17: 50 | I17: 50 | J17: Recebido | K17: =IF(J17="","",IF(OR(J17="Recebido",F17=""),MAX(0,F17-E17),MAX(0,$B$4-E17))) | L17: =IF(K17="","",IF(K17=0,"Em dia",IF(K17<=30,"1-30 dias",IF(K17<=60,"31-60 dias",IF(K17<=90,"61-90 dias",">90 dias"))))) | M17: Origem: CR mar/2026. Tipo original: Fixo. Doc/NF: 88. | N17: 46082 | O17: Receita recorrente | P17: =IF(C17="","",IF(ISNUMBER(SEARCH("PCMSO",C17)),"PCMSO",IF(OR(ISNUMBER(SEARCH("E-SOCIAL",C17)),ISNUMBER(SEARCH("PSICOSOCIAL",C17))),"eSocial / Psicossocial",IF(O17="Receita recorrente","Carteira recorrente","Projetos / Laudos / Avulsos")))) | Q17: =IF(P17="","",IF(P17="Carteira recorrente","Operação recorrente",IF(P17="PCMSO","Projetos PCMSO",IF(P17="eSocial / Psicossocial","Projetos eSocial/Psicossocial","Projetos / Laudos / Avulsos")))) | R17: =IF(C17="","",IF(ISNUMBER(SEARCH("PCMSO",C17)),"Título com PCMSO no nome",IF(OR(ISNUMBER(SEARCH("E-SOCIAL",C17)),ISNUMBER(SEARCH("PSICOSOCIAL",C17))),"Título com eSocial/Psicossocial no nome",IF(O17="Receita recorrente","Tipo DRE recorrente","Extra sem palavra-chave específica")))) | S17: =IFERROR(VLOOKUP($A17,'13. Mapa Títulos-Receita'!$A$8:$P$1000,4,FALSE),"") | T17: =IFERROR(VLOOKUP($A17,'13. Mapa Títulos-Receita'!$A$8:$P$1000,5,FALSE),"") | U17: =IFERROR(VLOOKUP($A17,'13. Mapa Títulos-Receita'!$A$8:$P$1000,6,FALSE),"") | V17: =IFERROR(VLOOKUP($A17,'13. Mapa Títulos-Receita'!$A$8:$P$1000,7,FALSE),"") | W17: =IFERROR(VLOOKUP($A17,'13. Mapa Títulos-Receita'!$A$8:$P$1000,8,FALSE),"") | X17: =IFERROR(VLOOKUP($A17,'13. Mapa Títulos-Receita'!$A$8:$P$1000,9,FALSE),"") | Y17: =IFERROR(VLOOKUP($A17,'13. Mapa Títulos-Receita'!$A$8:$P$1000,10,FALSE),"") | Z17: =IFERROR(VLOOKUP($A17,'13. Mapa Títulos-Receita'!$A$8:$P$1000,11,FALSE),"") | AA17: =IFERROR(VLOOKUP($A17,'13. Mapa Títulos-Receita'!$A$8:$P$1000,12,FALSE),"") | AB17: =IFERROR(VLOOKUP($A17,'13. Mapa Títulos-Receita'!$A$8:$P$1000,13,FALSE),"") | AC17: =IFERROR(VLOOKUP($A17,'13. Mapa Títulos-Receita'!$A$8:$P$1000,14,FALSE),"") | AD17: =IFERROR(VLOOKUP($A17,'13. Mapa Títulos-Receita'!$A$8:$P$1000,15,FALSE),"") | AE17: =IFERROR(VLOOKUP($A17,'13. Mapa Títulos-Receita'!$A$8:$P$1000,16,FALSE),"")
A18: CR-011 | B18: RUITHER | C18: RUITHER | D18: 46086 | E18: 46086 | F18: 46083 | H18: 50 | I18: 50 | J18: Recebido | K18: =IF(J18="","",IF(OR(J18="Recebido",F18=""),MAX(0,F18-E18),MAX(0,$B$4-E18))) | L18: =IF(K18="","",IF(K18=0,"Em dia",IF(K18<=30,"1-30 dias",IF(K18<=60,"31-60 dias",IF(K18<=90,"61-90 dias",">90 dias"))))) | M18: Origem: CR mar/2026. Tipo original: Fixo. Doc/NF: 89. | N18: 46082 | O18: Receita recorrente | P18: =IF(C18="","",IF(ISNUMBER(SEARCH("PCMSO",C18)),"PCMSO",IF(OR(ISNUMBER(SEARCH("E-SOCIAL",C18)),ISNUMBER(SEARCH("PSICOSOCIAL",C18))),"eSocial / Psicossocial",IF(O18="Receita recorrente","Carteira recorrente","Projetos / Laudos / Avulsos")))) | Q18: =IF(P18="","",IF(P18="Carteira recorrente","Operação recorrente",IF(P18="PCMSO","Projetos PCMSO",IF(P18="eSocial / Psicossocial","Projetos eSocial/Psicossocial","Projetos / Laudos / Avulsos")))) | R18: =IF(C18="","",IF(ISNUMBER(SEARCH("PCMSO",C18)),"Título com PCMSO no nome",IF(OR(ISNUMBER(SEARCH("E-SOCIAL",C18)),ISNUMBER(SEARCH("PSICOSOCIAL",C18))),"Título com eSocial/Psicossocial no nome",IF(O18="Receita recorrente","Tipo DRE recorrente","Extra sem palavra-chave específica")))) | S18: =IFERROR(VLOOKUP($A18,'13. Mapa Títulos-Receita'!$A$8:$P$1000,4,FALSE),"") | T18: =IFERROR(VLOOKUP($A18,'13. Mapa Títulos-Receita'!$A$8:$P$1000,5,FALSE),"") | U18: =IFERROR(VLOOKUP($A18,'13. Mapa Títulos-Receita'!$A$8:$P$1000,6,FALSE),"") | V18: =IFERROR(VLOOKUP($A18,'13. Mapa Títulos-Receita'!$A$8:$P$1000,7,FALSE),"") | W18: =IFERROR(VLOOKUP($A18,'13. Mapa Títulos-Receita'!$A$8:$P$1000,8,FALSE),"") | X18: =IFERROR(VLOOKUP($A18,'13. Mapa Títulos-Receita'!$A$8:$P$1000,9,FALSE),"") | Y18: =IFERROR(VLOOKUP($A18,'13. Mapa Títulos-Receita'!$A$8:$P$1000,10,FALSE),"") | Z18: =IFERROR(VLOOKUP($A18,'13. Mapa Títulos-Receita'!$A$8:$P$1000,11,FALSE),"") | AA18: =IFERROR(VLOOKUP($A18,'13. Mapa Títulos-Receita'!$A$8:$P$1000,12,FALSE),"") | AB18: =IFERROR(VLOOKUP($A18,'13. Mapa Títulos-Receita'!$A$8:$P$1000,13,FALSE),"") | AC18: =IFERROR(VLOOKUP($A18,'13. Mapa Títulos-Receita'!$A$8:$P$1000,14,FALSE),"") | AD18: =IFERROR(VLOOKUP($A18,'13. Mapa Títulos-Receita'!$A$8:$P$1000,15,FALSE),"") | AE18: =IFERROR(VLOOKUP($A18,'13. Mapa Títulos-Receita'!$A$8:$P$1000,16,FALSE),"")
A19: CR-012 | B19: S12 INCORPORAÇÃO | C19: S12 INCORPORAÇÃO | D19: 46086 | E19: 46086 | F19: 46083 | H19: 40 | I19: 40 | J19: Recebido | K19: =IF(J19="","",IF(OR(J19="Recebido",F19=""),MAX(0,F19-E19),MAX(0,$B$4-E19))) | L19: =IF(K19="","",IF(K19=0,"Em dia",IF(K19<=30,"1-30 dias",IF(K19<=60,"31-60 dias",IF(K19<=90,"61-90 dias",">90 dias"))))) | M19: Origem: CR mar/2026. Tipo original: Fixo. Doc/NF: 90. | N19: 46082 | O19: Receita recorrente | P19: =IF(C19="","",IF(ISNUMBER(SEARCH("PCMSO",C19)),"PCMSO",IF(OR(ISNUMBER(SEARCH("E-SOCIAL",C19)),ISNUMBER(SEARCH("PSICOSOCIAL",C19))),"eSocial / Psicossocial",IF(O19="Receita recorrente","Carteira recorrente","Projetos / Laudos / Avulsos")))) | Q19: =IF(P19="","",IF(P19="Carteira recorrente","Operação recorrente",IF(P19="PCMSO","Projetos PCMSO",IF(P19="eSocial / Psicossocial","Projetos eSocial/Psicossocial","Projetos / Laudos / Avulsos")))) | R19: =IF(C19="","",IF(ISNUMBER(SEARCH("PCMSO",C19)),"Título com PCMSO no nome",IF(OR(ISNUMBER(SEARCH("E-SOCIAL",C19)),ISNUMBER(SEARCH("PSICOSOCIAL",C19))),"Título com eSocial/Psicossocial no nome",IF(O19="Receita recorrente","Tipo DRE recorrente","Extra sem palavra-chave específica")))) | S19: =IFERROR(VLOOKUP($A19,'13. Mapa Títulos-Receita'!$A$8:$P$1000,4,FALSE),"") | T19: =IFERROR(VLOOKUP($A19,'13. Mapa Títulos-Receita'!$A$8:$P$1000,5,FALSE),"") | U19: =IFERROR(VLOOKUP($A19,'13. Mapa Títulos-Receita'!$A$8:$P$1000,6,FALSE),"") | V19: =IFERROR(VLOOKUP($A19,'13. Mapa Títulos-Receita'!$A$8:$P$1000,7,FALSE),"") | W19: =IFERROR(VLOOKUP($A19,'13. Mapa Títulos-Receita'!$A$8:$P$1000,8,FALSE),"") | X19: =IFERROR(VLOOKUP($A19,'13. Mapa Títulos-Receita'!$A$8:$P$1000,9,FALSE),"") | Y19: =IFERROR(VLOOKUP($A19,'13. Mapa Títulos-Receita'!$A$8:$P$1000,10,FALSE),"") | Z19: =IFERROR(VLOOKUP($A19,'13. Mapa Títulos-Receita'!$A$8:$P$1000,11,FALSE),"") | AA19: =IFERROR(VLOOKUP($A19,'13. Mapa Títulos-Receita'!$A$8:$P$1000,12,FALSE),"") | AB19: =IFERROR(VLOOKUP($A19,'13. Mapa Títulos-Receita'!$A$8:$P$1000,13,FALSE),"") | AC19: =IFERROR(VLOOKUP($A19,'13. Mapa Títulos-Receita'!$A$8:$P$1000,14,FALSE),"") | AD19: =IFERROR(VLOOKUP($A19,'13. Mapa Títulos-Receita'!$A$8:$P$1000,15,FALSE),"") | AE19: =IFERROR(VLOOKUP($A19,'13. Mapa Títulos-Receita'!$A$8:$P$1000,16,FALSE),"")
... A25: CR-018 | B25: TRANSPORTADORA RODOMEU | C25: TRANSPORTADORA RODOMEU | D25: 46096 | E25: 46096 | F25: 46097 | H25: 100 | I25: 100 | J25: Recebido | K25: =IF(J25="","",IF(OR(J25="Recebido",F25=""),MAX(0,F25-E25),MAX(0,$B$4-E25))) | L25: =IF(K25="","",IF(K25=0,"Em dia",IF(K25<=30,"1-30 dias",IF(K25<=60,"31-60 dias",IF(K25<=90,"61-90 dias",">90 dias"))))) | M25: Origem: CR mar/2026. Tipo original: Fixo. Doc/NF: 111. | N25: 46082 | O25: Receita recorrente | P25: =IF(C25="","",IF(ISNUMBER(SEARCH("PCMSO",C25)),"PCMSO",IF(OR(ISNUMBER(SEARCH("E-SOCIAL",C25)),ISNUMBER(SEARCH("PSICOSOCIAL",C25))),"eSocial / Psicossocial",IF(O25="Receita recorrente","Carteira recorrente","Projetos / Laudos / Avulsos")))) | Q25: =IF(P25="","",IF(P25="Carteira recorrente","Operação recorrente",IF(P25="PCMSO","Projetos PCMSO",IF(P25="eSocial / Psicossocial","Projetos eSocial/Psicossocial","Projetos / Laudos / Avulsos")))) | R25: =IF(C25="","",IF(ISNUMBER(SEARCH("PCMSO",C25)),"Título com PCMSO no nome",IF(OR(ISNUMBER(SEARCH("E-SOCIAL",C25)),ISNUMBER(SEARCH("PSICOSOCIAL",C25))),"Título com eSocial/Psicossocial no nome",IF(O25="Receita recorrente","Tipo DRE recorrente","Extra sem palavra-chave específica")))) | S25: =IFERROR(VLOOKUP($A25,'13. Mapa Títulos-Receita'!$A$8:$P$1000,4,FALSE),"") | T25: =IFERROR(VLOOKUP($A25,'13. Mapa Títulos-Receita'!$A$8:$P$1000,5,FALSE),"") | U25: =IFERROR(VLOOKUP($A25,'13. Mapa Títulos-Receita'!$A$8:$P$1000,6,FALSE),"") | V25: =IFERROR(VLOOKUP($A25,'13. Mapa Títulos-Receita'!$A$8:$P$1000,7,FALSE),"") | W25: =IFERROR(VLOOKUP($A25,'13. Mapa Títulos-Receita'!$A$8:$P$1000,8,FALSE),"") | X25: =IFERROR(VLOOKUP($A25,'13. Mapa Títulos-Receita'!$A$8:$P$1000,9,FALSE),"") | Y25: =IFERROR(VLOOKUP($A25,'13. Mapa Títulos-Receita'!$A$8:$P$1000,10,FALSE),"") | Z25: =IFERROR(VLOOKUP($A25,'13. Mapa Títulos-Receita'!$A$8:$P$1000,11,FALSE),"") | AA25: =IFERROR(VLOOKUP($A25,'13. Mapa Títulos-Receita'!$A$8:$P$1000,12,FALSE),"") | AB25: =IFERROR(VLOOKUP($A25,'13. Mapa Títulos-Receita'!$A$8:$P$1000,13,FALSE),"") | AC25: =IFERROR(VLOOKUP($A25,'13. Mapa Títulos-Receita'!$A$8:$P$1000,14,FALSE),"") | AD25: =IFERROR(VLOOKUP($A25,'13. Mapa Títulos-Receita'!$A$8:$P$1000,15,FALSE),"") | AE25: =IFERROR(VLOOKUP($A25,'13. Mapa Títulos-Receita'!$A$8:$P$1000,16,FALSE),"")
A26: CR-019 | B26: AGROFORTE | C26: AGROFORTE (10/12) | D26: 46086 | E26: 46086 | F26: 46087 | G26: 10/12 | H26: 973 | I26: 973 | J26: Recebido | K26: =IF(J26="","",IF(OR(J26="Recebido",F26=""),MAX(0,F26-E26),MAX(0,$B$4-E26))) | L26: =IF(K26="","",IF(K26=0,"Em dia",IF(K26<=30,"1-30 dias",IF(K26<=60,"31-60 dias",IF(K26<=90,"61-90 dias",">90 dias"))))) | M26: Origem: CR mar/2026. Tipo original: Fixo. Doc/NF: 87. parcela 10/12 | N26: 46082 | O26: Receita recorrente | P26: =IF(C26="","",IF(ISNUMBER(SEARCH("PCMSO",C26)),"PCMSO",IF(OR(ISNUMBER(SEARCH("E-SOCIAL",C26)),ISNUMBER(SEARCH("PSICOSOCIAL",C26))),"eSocial / Psicossocial",IF(O26="Receita recorrente","Carteira recorrente","Projetos / Laudos / Avulsos")))) | Q26: =IF(P26="","",IF(P26="Carteira recorrente","Operação recorrente",IF(P26="PCMSO","Projetos PCMSO",IF(P26="eSocial / Psicossocial","Projetos eSocial/Psicossocial","Projetos / Laudos / Avulsos")))) | R26: =IF(C26="","",IF(ISNUMBER(SEARCH("PCMSO",C26)),"Título com PCMSO no nome",IF(OR(ISNUMBER(SEARCH("E-SOCIAL",C26)),ISNUMBER(SEARCH("PSICOSOCIAL",C26))),"Título com eSocial/Psicossocial no nome",IF(O26="Receita recorrente","Tipo DRE recorrente","Extra sem palavra-chave específica")))) | S26: =IFERROR(VLOOKUP($A26,'13. Mapa Títulos-Receita'!$A$8:$P$1000,4,FALSE),"") | T26: =IFERROR(VLOOKUP($A26,'13. Mapa Títulos-Receita'!$A$8:$P$1000,5,FALSE),"") | U26: =IFERROR(VLOOKUP($A26,'13. Mapa Títulos-Receita'!$A$8:$P$1000,6,FALSE),"") | V26: =IFERROR(VLOOKUP($A26,'13. Mapa Títulos-Receita'!$A$8:$P$1000,7,FALSE),"") | W26: =IFERROR(VLOOKUP($A26,'13. Mapa Títulos-Receita'!$A$8:$P$1000,8,FALSE),"") | X26: =IFERROR(VLOOKUP($A26,'13. Mapa Títulos-Receita'!$A$8:$P$1000,9,FALSE),"") | Y26: =IFERROR(VLOOKUP($A26,'13. Mapa Títulos-Receita'!$A$8:$P$1000,10,FALSE),"") | Z26: =IFERROR(VLOOKUP($A26,'13. Mapa Títulos-Receita'!$A$8:$P$1000,11,FALSE),"") | AA26: =IFERROR(VLOOKUP($A26,'13. Mapa Títulos-Receita'!$A$8:$P$1000,12,FALSE),"") | AB26: =IFERROR(VLOOKUP($A26,'13. Mapa Títulos-Receita'!$A$8:$P$1000,13,FALSE),"") | AC26: =IFERROR(VLOOKUP($A26,'13. Mapa Títulos-Receita'!$A$8:$P$1000,14,FALSE),"") | AD26: =IFERROR(VLOOKUP($A26,'13. Mapa Títulos-Receita'!$A$8:$P$1000,15,FALSE),"") | AE26: =IFERROR(VLOOKUP($A26,'13. Mapa Títulos-Receita'!$A$8:$P$1000,16,FALSE),"")
A27: CR-020 | B27: FAZENDAS GUARACI | C27: FAZENDAS GUARACI | D27: 46098 | E27: 46098 | F27: 46098 | H27: 140 | I27: 140 | J27: Recebido | K27: =IF(J27="","",IF(OR(J27="Recebido",F27=""),MAX(0,F27-E27),MAX(0,$B$4-E27))) | L27: =IF(K27="","",IF(K27=0,"Em dia",IF(K27<=30,"1-30 dias",IF(K27<=60,"31-60 dias",IF(K27<=90,"61-90 dias",">90 dias"))))) | M27: Origem: CR mar/2026. Tipo original: Fixo. Doc/NF: S/N. | N27: 46082 | O27: Receita recorrente | P27: =IF(C27="","",IF(ISNUMBER(SEARCH("PCMSO",C27)),"PCMSO",IF(OR(ISNUMBER(SEARCH("E-SOCIAL",C27)),ISNUMBER(SEARCH("PSICOSOCIAL",C27))),"eSocial / Psicossocial",IF(O27="Receita recorrente","Carteira recorrente","Projetos / Laudos / Avulsos")))) | Q27: =IF(P27="","",IF(P27="Carteira recorrente","Operação recorrente",IF(P27="PCMSO","Projetos PCMSO",IF(P27="eSocial / Psicossocial","Projetos eSocial/Psicossocial","Projetos / Laudos / Avulsos")))) | R27: =IF(C27="","",IF(ISNUMBER(SEARCH("PCMSO",C27)),"Título com PCMSO no nome",IF(OR(ISNUMBER(SEARCH("E-SOCIAL",C27)),ISNUMBER(SEARCH("PSICOSOCIAL",C27))),"Título com eSocial/Psicossocial no nome",IF(O27="Receita recorrente","Tipo DRE recorrente","Extra sem palavra-chave específica")))) | S27: =IFERROR(VLOOKUP($A27,'13. Mapa Títulos-Receita'!$A$8:$P$1000,4,FALSE),"") | T27: =IFERROR(VLOOKUP($A27,'13. Mapa Títulos-Receita'!$A$8:$P$1000,5,FALSE),"") | U27: =IFERROR(VLOOKUP($A27,'13. Mapa Títulos-Receita'!$A$8:$P$1000,6,FALSE),"") | V27: =IFERROR(VLOOKUP($A27,'13. Mapa Títulos-Receita'!$A$8:$P$1000,7,FALSE),"") | W27: =IFERROR(VLOOKUP($A27,'13. Mapa Títulos-Receita'!$A$8:$P$1000,8,FALSE),"") | X27: =IFERROR(VLOOKUP($A27,'13. Mapa Títulos-Receita'!$A$8:$P$1000,9,FALSE),"") | Y27: =IFERROR(VLOOKUP($A27,'13. Mapa Títulos-Receita'!$A$8:$P$1000,10,FALSE),"") | Z27: =IFERROR(VLOOKUP($A27,'13. Mapa Títulos-Receita'!$A$8:$P$1000,11,FALSE),"") | AA27: =IFERROR(VLOOKUP($A27,'13. Mapa Títulos-Receita'!$A$8:$P$1000,12,FALSE),"") | AB27: =IFERROR(VLOOKUP($A27,'13. Mapa Títulos-Receita'!$A$8:$P$1000,13,FALSE),"") | AC27: =IFERROR(VLOOKUP($A27,'13. Mapa Títulos-Receita'!$A$8:$P$1000,14,FALSE),"") | AD27: =IFERROR(VLOOKUP($A27,'13. Mapa Títulos-Receita'!$A$8:$P$1000,15,FALSE),"") | AE27: =IFERROR(VLOOKUP($A27,'13. Mapa Títulos-Receita'!$A$8:$P$1000,16,FALSE),"")
A28: CR-021 | B28: TR. LASER - INCL FUNÇÃO | C28: TR. LASER - INCL FUNÇÃO | D28: 46087 | E28: 46087 | F28: 46084 | H28: 350 | I28: 350 | J28: Recebido | K28: =IF(J28="","",IF(OR(J28="Recebido",F28=""),MAX(0,F28-E28),MAX(0,$B$4-E28))) | L28: =IF(K28="","",IF(K28=0,"Em dia",IF(K28<=30,"1-30 dias",IF(K28<=60,"31-60 dias",IF(K28<=90,"61-90 dias",">90 dias"))))) | M28: Origem: CR mar/2026. Tipo original: Extra. Doc/NF: 78. | N28: 46082 | O28: Receita extra | P28: =IF(C28="","",IF(ISNUMBER(SEARCH("PCMSO",C28)),"PCMSO",IF(OR(ISNUMBER(SEARCH("E-SOCIAL",C28)),ISNUMBER(SEARCH("PSICOSOCIAL",C28))),"eSocial / Psicossocial",IF(O28="Receita recorrente","Carteira recorrente","Projetos / Laudos / Avulsos")))) | Q28: =IF(P28="","",IF(P28="Carteira recorrente","Operação recorrente",IF(P28="PCMSO","Projetos PCMSO",IF(P28="eSocial / Psicossocial","Projetos eSocial/Psicossocial","Projetos / Laudos / Avulsos")))) | R28: =IF(C28="","",IF(ISNUMBER(SEARCH("PCMSO",C28)),"Título com PCMSO no nome",IF(OR(ISNUMBER(SEARCH("E-SOCIAL",C28)),ISNUMBER(SEARCH("PSICOSOCIAL",C28))),"Título com eSocial/Psicossocial no nome",IF(O28="Receita recorrente","Tipo DRE recorrente","Extra sem palavra-chave específica")))) | S28: =IFERROR(VLOOKUP($A28,'13. Mapa Títulos-Receita'!$A$8:$P$1000,4,FALSE),"") | T28: =IFERROR(VLOOKUP($A28,'13. Mapa Títulos-Receita'!$A$8:$P$1000,5,FALSE),"") | U28: =IFERROR(VLOOKUP($A28,'13. Mapa Títulos-Receita'!$A$8:$P$1000,6,FALSE),"") | V28: =IFERROR(VLOOKUP($A28,'13. Mapa Títulos-Receita'!$A$8:$P$1000,7,FALSE),"") | W28: =IFERROR(VLOOKUP($A28,'13. Mapa Títulos-Receita'!$A$8:$P$1000,8,FALSE),"") | X28: =IFERROR(VLOOKUP($A28,'13. Mapa Títulos-Receita'!$A$8:$P$1000,9,FALSE),"") | Y28: =IFERROR(VLOOKUP($A28,'13. Mapa Títulos-Receita'!$A$8:$P$1000,10,FALSE),"") | Z28: =IFERROR(VLOOKUP($A28,'13. Mapa Títulos-Receita'!$A$8:$P$1000,11,FALSE),"") | AA28: =IFERROR(VLOOKUP($A28,'13. Mapa Títulos-Receita'!$A$8:$P$1000,12,FALSE),"") | AB28: =IFERROR(VLOOKUP($A28,'13. Mapa Títulos-Receita'!$A$8:$P$1000,13,FALSE),"") | AC28: =IFERROR(VLOOKUP($A28,'13. Mapa Títulos-Receita'!$A$8:$P$1000,14,FALSE),"") | AD28: =IFERROR(VLOOKUP($A28,'13. Mapa Títulos-Receita'!$A$8:$P$1000,15,FALSE),"") | AE28: =IFERROR(VLOOKUP($A28,'13. Mapa Títulos-Receita'!$A$8:$P$1000,16,FALSE),"")
A29: CR-022 | B29: DPA- HUB UM 593 | C29: DPA- HUB UM 593 | D29: 46094 | E29: 46094 | F29: 46097 | H29: 800 | I29: 800 | J29: Recebido | K29: =IF(J29="","",IF(OR(J29="Recebido",F29=""),MAX(0,F29-E29),MAX(0,$B$4-E29))) | L29: =IF(K29="","",IF(K29=0,"Em dia",IF(K29<=30,"1-30 dias",IF(K29<=60,"31-60 dias",IF(K29<=90,"61-90 dias",">90 dias"))))) | M29: Origem: CR mar/2026. Tipo original: Extra. Doc/NF: 77. | N29: 46082 | O29: Receita extra | P29: =IF(C29="","",IF(ISNUMBER(SEARCH("PCMSO",C29)),"PCMSO",IF(OR(ISNUMBER(SEARCH("E-SOCIAL",C29)),ISNUMBER(SEARCH("PSICOSOCIAL",C29))),"eSocial / Psicossocial",IF(O29="Receita recorrente","Carteira recorrente","Projetos / Laudos / Avulsos")))) | Q29: =IF(P29="","",IF(P29="Carteira recorrente","Operação recorrente",IF(P29="PCMSO","Projetos PCMSO",IF(P29="eSocial / Psicossocial","Projetos eSocial/Psicossocial","Projetos / Laudos / Avulsos")))) | R29: =IF(C29="","",IF(ISNUMBER(SEARCH("PCMSO",C29)),"Título com PCMSO no nome",IF(OR(ISNUMBER(SEARCH("E-SOCIAL",C29)),ISNUMBER(SEARCH("PSICOSOCIAL",C29))),"Título com eSocial/Psicossocial no nome",IF(O29="Receita recorrente","Tipo DRE recorrente","Extra sem palavra-chave específica")))) | S29: =IFERROR(VLOOKUP($A29,'13. Mapa Títulos-Receita'!$A$8:$P$1000,4,FALSE),"") | T29: =IFERROR(VLOOKUP($A29,'13. Mapa Títulos-Receita'!$A$8:$P$1000,5,FALSE),"") | U29: =IFERROR(VLOOKUP($A29,'13. Mapa Títulos-Receita'!$A$8:$P$1000,6,FALSE),"") | V29: =IFERROR(VLOOKUP($A29,'13. Mapa Títulos-Receita'!$A$8:$P$1000,7,FALSE),"") | W29: =IFERROR(VLOOKUP($A29,'13. Mapa Títulos-Receita'!$A$8:$P$1000,8,FALSE),"") | X29: =IFERROR(VLOOKUP($A29,'13. Mapa Títulos-Receita'!$A$8:$P$1000,9,FALSE),"") | Y29: =IFERROR(VLOOKUP($A29,'13. Mapa Títulos-Receita'!$A$8:$P$1000,10,FALSE),"") | Z29: =IFERROR(VLOOKUP($A29,'13. Mapa Títulos-Receita'!$A$8:$P$1000,11,FALSE),"") | AA29: =IFERROR(VLOOKUP($A29,'13. Mapa Títulos-Receita'!$A$8:$P$1000,12,FALSE),"") | AB29: =IFERROR(VLOOKUP($A29,'13. Mapa Títulos-Receita'!$A$8:$P$1000,13,FALSE),"") | AC29: =IFERROR(VLOOKUP($A29,'13. Mapa Títulos-Receita'!$A$8:$P$1000,14,FALSE),"") | AD29: =IFERROR(VLOOKUP($A29,'13. Mapa Títulos-Receita'!$A$8:$P$1000,15,FALSE),"") | AE29: =IFERROR(VLOOKUP($A29,'13. Mapa Títulos-Receita'!$A$8:$P$1000,16,FALSE),"")
A30: CR-023 | B30: LCA - FRIGOPAIVA /FERRO VELHO | C30: LCA - FRIGOPAIVA /FERRO VELHO (1/3) | D30: 46098 | E30: 46098 | F30: 46098 | G30: 1/3 | H30: 733.33 | I30: 733.33 | J30: Recebido | K30: =IF(J30="","",IF(OR(J30="Recebido",F30=""),MAX(0,F30-E30),MAX(0,$B$4-E30))) | L30: =IF(K30="","",IF(K30=0,"Em dia",IF(K30<=30,"1-30 dias",IF(K30<=60,"31-60 dias",IF(K30<=90,"61-90 dias",">90 dias"))))) | M30: Origem: CR mar/2026. Tipo original: Extra. Doc/NF: S/N. parcela 1/3 | N30: 46082 | O30: Receita extra | P30: =IF(C30="","",IF(ISNUMBER(SEARCH("PCMSO",C30)),"PCMSO",IF(OR(ISNUMBER(SEARCH("E-SOCIAL",C30)),ISNUMBER(SEARCH("PSICOSOCIAL",C30))),"eSocial / Psicossocial",IF(O30="Receita recorrente","Carteira recorrente","Projetos / Laudos / Avulsos")))) | Q30: =IF(P30="","",IF(P30="Carteira recorrente","Operação recorrente",IF(P30="PCMSO","Projetos PCMSO",IF(P30="eSocial / Psicossocial","Projetos eSocial/Psicossocial","Projetos / Laudos / Avulsos")))) | R30: =IF(C30="","",IF(ISNUMBER(SEARCH("PCMSO",C30)),"Título com PCMSO no nome",IF(OR(ISNUMBER(SEARCH("E-SOCIAL",C30)),ISNUMBER(SEARCH("PSICOSOCIAL",C30))),"Título com eSocial/Psicossocial no nome",IF(O30="Receita recorrente","Tipo DRE recorrente","Extra sem palavra-chave específica")))) | S30: =IFERROR(VLOOKUP($A30,'13. Mapa Títulos-Receita'!$A$8:$P$1000,4,FALSE),"") | T30: =IFERROR(VLOOKUP($A30,'13. Mapa Títulos-Receita'!$A$8:$P$1000,5,FALSE),"") | U30: =IFERROR(VLOOKUP($A30,'13. Mapa Títulos-Receita'!$A$8:$P$1000,6,FALSE),"") | V30: =IFERROR(VLOOKUP($A30,'13. Mapa Títulos-Receita'!$A$8:$P$1000,7,FALSE),"") | W30: =IFERROR(VLOOKUP($A30,'13. Mapa Títulos-Receita'!$A$8:$P$1000,8,FALSE),"") | X30: =IFERROR(VLOOKUP($A30,'13. Mapa Títulos-Receita'!$A$8:$P$1000,9,FALSE),"") | Y30: =IFERROR(VLOOKUP($A30,'13. Mapa Títulos-Receita'!$A$8:$P$1000,10,FALSE),"") | Z30: =IFERROR(VLOOKUP($A30,'13. Mapa Títulos-Receita'!$A$8:$P$1000,11,FALSE),"") | AA30: =IFERROR(VLOOKUP($A30,'13. Mapa Títulos-Receita'!$A$8:$P$1000,12,FALSE),"") | AB30: =IFERROR(VLOOKUP($A30,'13. Mapa Títulos-Receita'!$A$8:$P$1000,13,FALSE),"") | AC30: =IFERROR(VLOOKUP($A30,'13. Mapa Títulos-Receita'!$A$8:$P$1000,14,FALSE),"") | AD30: =IFERROR(VLOOKUP($A30,'13. Mapa Títulos-Receita'!$A$8:$P$1000,15,FALSE),"") | AE30: =IFERROR(VLOOKUP($A30,'13. Mapa Títulos-Receita'!$A$8:$P$1000,16,FALSE),"")
A31: CR-024 | B31: MDA SOLUÇÕES | C31: MDA SOLUÇÕES (2/3) | D31: 46099 | E31: 46099 | F31: 46101 | G31: 2/3 | H31: 1855 | I31: 1855 | J31: Recebido | K31: =IF(J31="","",IF(OR(J31="Recebido",F31=""),MAX(0,F31-E31),MAX(0,$B$4-E31))) | L31: =IF(K31="","",IF(K31=0,"Em dia",IF(K31<=30,"1-30 dias",IF(K31<=60,"31-60 dias",IF(K31<=90,"61-90 dias",">90 dias"))))) | M31: Origem: CR mar/2026. Tipo original: Extra. Doc/NF: 114. parcela 2/3 | N31: 46082 | O31: Receita extra | P31: =IF(C31="","",IF(ISNUMBER(SEARCH("PCMSO",C31)),"PCMSO",IF(OR(ISNUMBER(SEARCH("E-SOCIAL",C31)),ISNUMBER(SEARCH("PSICOSOCIAL",C31))),"eSocial / Psicossocial",IF(O31="Receita recorrente","Carteira recorrente","Projetos / Laudos / Avulsos")))) | Q31: =IF(P31="","",IF(P31="Carteira recorrente","Operação recorrente",IF(P31="PCMSO","Projetos PCMSO",IF(P31="eSocial / Psicossocial","Projetos eSocial/Psicossocial","Projetos / Laudos / Avulsos")))) | R31: =IF(C31="","",IF(ISNUMBER(SEARCH("PCMSO",C31)),"Título com PCMSO no nome",IF(OR(ISNUMBER(SEARCH("E-SOCIAL",C31)),ISNUMBER(SEARCH("PSICOSOCIAL",C31))),"Título com eSocial/Psicossocial no nome",IF(O31="Receita recorrente","Tipo DRE recorrente","Extra sem palavra-chave específica")))) | S31: =IFERROR(VLOOKUP($A31,'13. Mapa Títulos-Receita'!$A$8:$P$1000,4,FALSE),"") | T31: =IFERROR(VLOOKUP($A31,'13. Mapa Títulos-Receita'!$A$8:$P$1000,5,FALSE),"") | U31: =IFERROR(VLOOKUP($A31,'13. Mapa Títulos-Receita'!$A$8:$P$1000,6,FALSE),"") | V31: =IFERROR(VLOOKUP($A31,'13. Mapa Títulos-Receita'!$A$8:$P$1000,7,FALSE),"") | W31: =IFERROR(VLOOKUP($A31,'13. Mapa Títulos-Receita'!$A$8:$P$1000,8,FALSE),"") | X31: =IFERROR(VLOOKUP($A31,'13. Mapa Títulos-Receita'!$A$8:$P$1000,9,FALSE),"") | Y31: =IFERROR(VLOOKUP($A31,'13. Mapa Títulos-Receita'!$A$8:$P$1000,10,FALSE),"") | Z31: =IFERROR(VLOOKUP($A31,'13. Mapa Títulos-Receita'!$A$8:$P$1000,11,FALSE),"") | AA31: =IFERROR(VLOOKUP($A31,'13. Mapa Títulos-Receita'!$A$8:$P$1000,12,FALSE),"") | AB31: =IFERROR(VLOOKUP($A31,'13. Mapa Títulos-Receita'!$A$8:$P$1000,13,FALSE),"") | AC31: =IFERROR(VLOOKUP($A31,'13. Mapa Títulos-Receita'!$A$8:$P$1000,14,FALSE),"") | AD31: =IFERROR(VLOOKUP($A31,'13. Mapa Títulos-Receita'!$A$8:$P$1000,15,FALSE),"") | AE31: =IFERROR(VLOOKUP($A31,'13. Mapa Títulos-Receita'!$A$8:$P$1000,16,FALSE),"")
A32: CR-025 | B32: CBA - MERC BELA VISTA/ P Olavo | C32: CBA - MERC BELA VISTA/ P Olavo | D32: 46099 | E32: 46099 | F32: 46100 | H32: 560 | I32: 560 | J32: Recebido | K32: =IF(J32="","",IF(OR(J32="Recebido",F32=""),MAX(0,F32-E32),MAX(0,$B$4-E32))) | L32: =IF(K32="","",IF(K32=0,"Em dia",IF(K32<=30,"1-30 dias",IF(K32<=60,"31-60 dias",IF(K32<=90,"61-90 dias",">90 dias"))))) | M32: Origem: CR mar/2026. Tipo original: Extra. Doc/NF: 106. | N32: 46082 | O32: Receita extra | P32: =IF(C32="","",IF(ISNUMBER(SEARCH("PCMSO",C32)),"PCMSO",IF(OR(ISNUMBER(SEARCH("E-SOCIAL",C32)),ISNUMBER(SEARCH("PSICOSOCIAL",C32))),"eSocial / Psicossocial",IF(O32="Receita recorrente","Carteira recorrente","Projetos / Laudos / Avulsos")))) | Q32: =IF(P32="","",IF(P32="Carteira recorrente","Operação recorrente",IF(P32="PCMSO","Projetos PCMSO",IF(P32="eSocial / Psicossocial","Projetos eSocial/Psicossocial","Projetos / Laudos / Avulsos")))) | R32: =IF(C32="","",IF(ISNUMBER(SEARCH("PCMSO",C32)),"Título com PCMSO no nome",IF(OR(ISNUMBER(SEARCH("E-SOCIAL",C32)),ISNUMBER(SEARCH("PSICOSOCIAL",C32))),"Título com eSocial/Psicossocial no nome",IF(O32="Receita recorrente","Tipo DRE recorrente","Extra sem palavra-chave específica")))) | S32: =IFERROR(VLOOKUP($A32,'13. Mapa Títulos-Receita'!$A$8:$P$1000,4,FALSE),"") | T32: =IFERROR(VLOOKUP($A32,'13. Mapa Títulos-Receita'!$A$8:$P$1000,5,FALSE),"") | U32: =IFERROR(VLOOKUP($A32,'13. Mapa Títulos-Receita'!$A$8:$P$1000,6,FALSE),"") | V32: =IFERROR(VLOOKUP($A32,'13. Mapa Títulos-Receita'!$A$8:$P$1000,7,FALSE),"") | W32: =IFERROR(VLOOKUP($A32,'13. Mapa Títulos-Receita'!$A$8:$P$1000,8,FALSE),"") | X32: =IFERROR(VLOOKUP($A32,'13. Mapa Títulos-Receita'!$A$8:$P$1000,9,FALSE),"") | Y32: =IFERROR(VLOOKUP($A32,'13. Mapa Títulos-Receita'!$A$8:$P$1000,10,FALSE),"") | Z32: =IFERROR(VLOOKUP($A32,'13. Mapa Títulos-Receita'!$A$8:$P$1000,11,FALSE),"") | AA32: =IFERROR(VLOOKUP($A32,'13. Mapa Títulos-Receita'!$A$8:$P$1000,12,FALSE),"") | AB32: =IFERROR(VLOOKUP($A32,'13. Mapa Títulos-Receita'!$A$8:$P$1000,13,FALSE),"") | AC32: =IFERROR(VLOOKUP($A32,'13. Mapa Títulos-Receita'!$A$8:$P$1000,14,FALSE),"") | AD32: =IFERROR(VLOOKUP($A32,'13. Mapa Títulos-Receita'!$A$8:$P$1000,15,FALSE),"") | AE32: =IFERROR(VLOOKUP($A32,'13. Mapa Títulos-Receita'!$A$8:$P$1000,16,FALSE),"")
A33: CR-026 | B33: FAZ KUENO/ ADEQ PSICOSOCIAL | C33: FAZ KUENO/ ADEQ PSICOSOCIAL | D33: 46099 | E33: 46099 | F33: 46100 | H33: 360 | I33: 360 | J33: Recebido | K33: =IF(J33="","",IF(OR(J33="Recebido",F33=""),MAX(0,F33-E33),MAX(0,$B$4-E33))) | L33: =IF(K33="","",IF(K33=0,"Em dia",IF(K33<=30,"1-30 dias",IF(K33<=60,"31-60 dias",IF(K33<=90,"61-90 dias",">90 dias"))))) | M33: Origem: CR mar/2026. Tipo original: Extra. Doc/NF: 116. | N33: 46082 | O33: Receita extra | P33: =IF(C33="","",IF(ISNUMBER(SEARCH("PCMSO",C33)),"PCMSO",IF(OR(ISNUMBER(SEARCH("E-SOCIAL",C33)),ISNUMBER(SEARCH("PSICOSOCIAL",C33))),"eSocial / Psicossocial",IF(O33="Receita recorrente","Carteira recorrente","Projetos / Laudos / Avulsos")))) | Q33: =IF(P33="","",IF(P33="Carteira recorrente","Operação recorrente",IF(P33="PCMSO","Projetos PCMSO",IF(P33="eSocial / Psicossocial","Projetos eSocial/Psicossocial","Projetos / Laudos / Avulsos")))) | R33: =IF(C33="","",IF(ISNUMBER(SEARCH("PCMSO",C33)),"Título com PCMSO no nome",IF(OR(ISNUMBER(SEARCH("E-SOCIAL",C33)),ISNUMBER(SEARCH("PSICOSOCIAL",C33))),"Título com eSocial/Psicossocial no nome",IF(O33="Receita recorrente","Tipo DRE recorrente","Extra sem palavra-chave específica")))) | S33: =IFERROR(VLOOKUP($A33,'13. Mapa Títulos-Receita'!$A$8:$P$1000,4,FALSE),"") | T33: =IFERROR(VLOOKUP($A33,'13. Mapa Títulos-Receita'!$A$8:$P$1000,5,FALSE),"") | U33: =IFERROR(VLOOKUP($A33,'13. Mapa Títulos-Receita'!$A$8:$P$1000,6,FALSE),"") | V33: =IFERROR(VLOOKUP($A33,'13. Mapa Títulos-Receita'!$A$8:$P$1000,7,FALSE),"") | W33: =IFERROR(VLOOKUP($A33,'13. Mapa Títulos-Receita'!$A$8:$P$1000,8,FALSE),"") | X33: =IFERROR(VLOOKUP($A33,'13. Mapa Títulos-Receita'!$A$8:$P$1000,9,FALSE),"") | Y33: =IFERROR(VLOOKUP($A33,'13. Mapa Títulos-Receita'!$A$8:$P$1000,10,FALSE),"") | Z33: =IFERROR(VLOOKUP($A33,'13. Mapa Títulos-Receita'!$A$8:$P$1000,11,FALSE),"") | AA33: =IFERROR(VLOOKUP($A33,'13. Mapa Títulos-Receita'!$A$8:$P$1000,12,FALSE),"") | AB33: =IFERROR(VLOOKUP($A33,'13. Mapa Títulos-Receita'!$A$8:$P$1000,13,FALSE),"") | AC33: =IFERROR(VLOOKUP($A33,'13. Mapa Títulos-Receita'!$A$8:$P$1000,14,FALSE),"") | AD33: =IFERROR(VLOOKUP($A33,'13. Mapa Títulos-Receita'!$A$8:$P$1000,15,FALSE),"") | AE33: =IFERROR(VLOOKUP($A33,'13. Mapa Títulos-Receita'!$A$8:$P$1000,16,FALSE),"")
